# 取消与超时

## 取消协程的执行

该 [launch](https://kotlin.github.io/kotlinx.coroutines/kotlinx-coroutines-core/kotlinx.coroutines/launch.html) 函数返回了一个可以被用来取消运行中的协程的 [Job](https://kotlin.github.io/kotlinx.coroutines/kotlinx-coroutines-core/kotlinx.coroutines/-job/index.html)

## 取消是协作的

协程的取消是 *协作* 的。一段协程代码必须协作才能被取消。 所有 `kotlinx.coroutines` 中的挂起函数都是 *可被取消的* 。它们检查协程的取消， 并在取消时抛出 [CancellationException](https://kotlin.github.io/kotlinx.coroutines/kotlinx-coroutines-core/kotlinx.coroutines/-cancellation-exception/index.html)。 然而，如果协程正在执行计算任务，并且没有检查取消的话，那么它是不能被取消的

## 使计算代码可取消

我们有两种方法来使执行计算的代码可以被取消。第一种方法是定期调用挂起函数来检查取消。对于这种目的 [yield](https://kotlin.github.io/kotlinx.coroutines/kotlinx-coroutines-core/kotlinx.coroutines/yield.html) 是一个好的选择。 另一种方法是显式的检查取消状态

## 在 `finally` 中释放资源

我们通常使用如下的方法处理在被取消时抛出 [CancellationException](https://kotlin.github.io/kotlinx.coroutines/kotlinx-coroutines-core/kotlinx.coroutines/-cancellation-exception/index.html) 的可被取消的挂起函数。比如说，`try {……} finally {……}` 表达式以及 Kotlin 的 `use` 函数一般在协程被取消的时候执行它们的终结动作

## 运行不能取消的代码块

在前一个例子中任何尝试在 `finally` 块中调用挂起函数的行为都会抛出 [CancellationException](https://kotlin.github.io/kotlinx.coroutines/kotlinx-coroutines-core/kotlinx.coroutines/-cancellation-exception/index.html)，因为这里持续运行的代码是可以被取消的。通常，这并不是一个问题，所有良好的关闭操作（关闭一个文件、取消一个作业、或是关闭任何一种通信通道）通常都是非阻塞的，并且不会调用任何挂起函数。然而，在真实的案例中，当你需要挂起一个被取消的协程，你可以将相应的代码包装在 `withContext(NonCancellable) {……}` 中，并使用 [withContext](https://kotlin.github.io/kotlinx.coroutines/kotlinx-coroutines-core/kotlinx.coroutines/with-context.html) 函数以及 [NonCancellable](https://kotlin.github.io/kotlinx.coroutines/kotlinx-coroutines-core/kotlinx.coroutines/-non-cancellable.html) 上下文

## 超时

由于取消只是一个例外，所有的资源都使用常用的方法来关闭。 如果你需要做一些各类使用超时的特别的额外操作，可以使用类似 [withTimeout](https://kotlin.github.io/kotlinx.coroutines/kotlinx-coroutines-core/kotlinx.coroutines/with-timeout.html) 的 [withTimeoutOrNull](https://kotlin.github.io/kotlinx.coroutines/kotlinx-coroutines-core/kotlinx.coroutines/with-timeout-or-null.html) 函数，并把这些会超时的代码包装在 `try {...} catch (e: TimeoutCancellationException) {...}` 代码块中，而 [withTimeoutOrNull](https://kotlin.github.io/kotlinx.coroutines/kotlinx-coroutines-core/kotlinx.coroutines/with-timeout-or-null.html) 通过返回 `null` 来进行超时操作，从而替代抛出一个异常