# 异常处理与监督

### 异常的传播

协程构建器有两种形式：自动传播异常（[launch](https://kotlin.github.io/kotlinx.coroutines/kotlinx-coroutines-core/kotlinx.coroutines/launch.html) 与 [actor](https://kotlin.github.io/kotlinx.coroutines/kotlinx-coroutines-core/kotlinx.coroutines.channels/actor.html)）或向用户暴露异常（[async](https://kotlin.github.io/kotlinx.coroutines/kotlinx-coroutines-core/kotlinx.coroutines/async.html) 与 [produce](https://kotlin.github.io/kotlinx.coroutines/kotlinx-coroutines-core/kotlinx.coroutines.channels/produce.html)）。 当这些构建器用于创建一个*根*协程时，即该协程不是另一个协程的*子*协程， 前者这类构建器将异常视为**未捕获**异常，类似 Java 的 `Thread.uncaughtExceptionHandler`， 而后者则依赖用户来最终消费异常，例如通过 [await](https://kotlin.github.io/kotlinx.coroutines/kotlinx-coroutines-core/kotlinx.coroutines/-deferred/await.html) 或 [receive](https://kotlin.github.io/kotlinx.coroutines/kotlinx-coroutines-core/kotlinx.coroutines.channels/-receive-channel/receive.html)

### CoroutineExceptionHandler

将**未捕获**异常打印到控制台的默认行为是可自定义的。 *根*协程中的 [CoroutineExceptionHandler](https://kotlin.github.io/kotlinx.coroutines/kotlinx-coroutines-core/kotlinx.coroutines/-coroutine-exception-handler/index.html) 上下文元素可以被用于这个根协程通用的 `catch` 块，及其所有可能自定义了异常处理的子协程。 它类似于 [`Thread.uncaughtExceptionHandler`](https://docs.oracle.com/javase/8/docs/api/java/lang/Thread.html#setUncaughtExceptionHandler(java.lang.Thread.UncaughtExceptionHandler)) 。 你无法从 `CoroutineExceptionHandler` 的异常中恢复。当调用处理者的时候，协程已经完成并带有相应的异常。通常，该处理者用于记录异常，显示某种错误消息，终止和（或）重新启动应用程序

`CoroutineExceptionHandler` 仅在**未捕获**的异常上调用 — 没有以其他任何方式处理的异常。 特别是，所有*子*协程（在另一个 [Job](https://kotlin.github.io/kotlinx.coroutines/kotlinx-coroutines-core/kotlinx.coroutines/-job/index.html) 上下文中创建的协程）委托<!– 它们的父协程处理它们的异常，然后它们也委托给其父协程，以此类推直到根协程， 因此永远不会使用在其上下文中设置的 `CoroutineExceptionHandler`。 除此之外，[async](https://kotlin.github.io/kotlinx.coroutines/kotlinx-coroutines-core/kotlinx.coroutines/async.html) 构建器始终会捕获所有异常并将其表示在结果 [Deferred](https://kotlin.github.io/kotlinx.coroutines/kotlinx-coroutines-core/kotlinx.coroutines/-deferred/index.html) 对象中， 因此它的 `CoroutineExceptionHandler` 也无效

### 取消与异常

取消与异常紧密相关。协程内部使用 `CancellationException` 来进行取消，这个异常会被所有的处理者忽略，所以那些可以被 `catch` 代码块捕获的异常仅仅应该被用来作为额外调试信息的资源。 当一个协程使用 [Job.cancel](https://kotlin.github.io/kotlinx.coroutines/kotlinx-coroutines-core/kotlinx.coroutines/-job/cancel.html) 取消的时候，它会被终止，但是它不会取消它的父协程

如果一个协程遇到了 `CancellationException` 以外的异常，它将使用该异常取消它的父协程。 这个行为无法被覆盖，并且用于为[结构化的并发（structured concurrency）](https://github.com/Kotlin/kotlinx.coroutines/blob/master/docs/composing-suspending-functions.md#structured-concurrency-with-async) 提供稳定的协程层级结构[CoroutineExceptionHandler](https://kotlin.github.io/kotlinx.coroutines/kotlinx-coroutines-core/kotlinx.coroutines/-coroutine-exception-handler/index.html) 的实现并不是用于子协程

当父协程的所有子协程都结束后，原始的异常才会被父协程处理

### 异常聚合

当协程的多个子协程因异常而失败时， 一般规则是“取第一个异常”，因此将处理第一个异常。 在第一个异常之后发生的所有其他异常都作为被抑制的异常绑定至第一个异常

取消异常是透明的，默认情况下是未包装的

### 监督

#### 监督作业

[SupervisorJob](https://kotlin.github.io/kotlinx.coroutines/kotlinx-coroutines-core/kotlinx.coroutines/-supervisor-job.html) 可以用于这些目的。 它类似于常规的 [Job](https://kotlin.github.io/kotlinx.coroutines/kotlinx-coroutines-core/kotlinx.coroutines/-job.html)，唯一的不同是：SupervisorJob 的取消只会向下传播

#### 监督作用域

对于*作用域*的并发，可以用 [supervisorScope](https://kotlin.github.io/kotlinx.coroutines/kotlinx-coroutines-core/kotlinx.coroutines/supervisor-scope.html) 来替代 [coroutineScope](https://kotlin.github.io/kotlinx.coroutines/kotlinx-coroutines-core/kotlinx.coroutines/coroutine-scope.html) 来实现相同的目的。它只会单向的传播并且当作业自身执行失败的时候将所有子作业全部取消。作业自身也会在所有的子作业执行结束前等待， 就像 [coroutineScope](https://kotlin.github.io/kotlinx.coroutines/kotlinx-coroutines-core/kotlinx.coroutines/coroutine-scope.html) 所做的那样

#### 监督协程中的异常

常规的作业和监督作业之间的另一个重要区别是异常处理。 监督协程中的每一个子作业应该通过异常处理机制处理自身的异常。 这种差异来自于子作业的执行失败不会传播给它的父作业的事实。 这意味着在 [supervisorScope](https://kotlin.github.io/kotlinx.coroutines/kotlinx-coroutines-core/kotlinx.coroutines/supervisor-scope.html) 内部直接启动的协程*确实*使用了设置在它们作用域内的 [CoroutineExceptionHandler](https://kotlin.github.io/kotlinx.coroutines/kotlinx-coroutines-core/kotlinx.coroutines/-coroutine-exception-handler/index.html)，与父协程的方式相同 